Workbook

Sheet Summary
A1: Dynamic Travel Backend - API Test Sheet
A2: Tool: Postman | Base URL: http://localhost:5000 | Database: MongoDB Atlas | Collection: Dynamic Travel Backend
A4: Total test cases | B4: =COUNTA('Test Cases'!$A$2:$A$500) -> 111
A5: Pass | B5: =COUNTIF('Test Cases'!$L$2:$L$500,"Pass") -> 0
A6: Fail | B6: =COUNTIF('Test Cases'!$L$2:$L$500,"Fail") -> 0
A7: Blocked | B7: =COUNTIF('Test Cases'!$L$2:$L$500,"Blocked") -> 0
A8: Not Run | B8: =COUNTIF('Test Cases'!$A$2:$A$500,"?*")-B5-B6-B7 -> 111
A9: Executed (Pass + Fail) | B9: =B5+B6 -> 0
A10: Pass rate (of executed) | B10: =IF(B9=0,0,B5/B9) -> 0
A11: Progress (executed / total) | B11: =IF(B4=0,0,(B5+B6+B7)/B4) -> 0
A13: Results by module
A14: Module | B14: Total | C14: Pass | D14: Fail | E14: Blocked | F14: Not Run | G14: Pass %
A15: System | B15: =COUNTIF('Test Cases'!$B$2:$B$500,$A15) -> 2 | C15: =COUNTIFS('Test Cases'!$B$2:$B$500,$A15,'Test Cases'!$L$2:$L$500,"Pass") -> 0 | D15: =COUNTIFS('Test Cases'!$B$2:$B$500,$A15,'Test Cases'!$L$2:$L$500,"Fail") -> 0 | E15: =COUNTIFS('Test Cases'!$B$2:$B$500,$A15,'Test Cases'!$L$2:$L$500,"Blocked") -> 0 | F15: =B15-C15-D15-E15 -> 2 | G15: =IF(C15+D15=0,0,C15/(C15+D15)) -> 0
A16: Auth - Register & OTP | B16: =COUNTIF('Test Cases'!$B$2:$B$500,$A16) -> 8 | C16: =COUNTIFS('Test Cases'!$B$2:$B$500,$A16,'Test Cases'!$L$2:$L$500,"Pass") -> 0 | D16: =COUNTIFS('Test Cases'!$B$2:$B$500,$A16,'Test Cases'!$L$2:$L$500,"Fail") -> 0 | E16: =COUNTIFS('Test Cases'!$B$2:$B$500,$A16,'Test Cases'!$L$2:$L$500,"Blocked") -> 0 | F16: =B16-C16-D16-E16 -> 8 | G16: =IF(C16+D16=0,0,C16/(C16+D16)) -> 0
A17: Auth - Login & Session | B17: =COUNTIF('Test Cases'!$B$2:$B$500,$A17) -> 15 | C17: =COUNTIFS('Test Cases'!$B$2:$B$500,$A17,'Test Cases'!$L$2:$L$500,"Pass") -> 0 | D17: =COUNTIFS('Test Cases'!$B$2:$B$500,$A17,'Test Cases'!$L$2:$L$500,"Fail") -> 0 | E17: =COUNTIFS('Test Cases'!$B$2:$B$500,$A17,'Test Cases'!$L$2:$L$500,"Blocked") -> 0 | F17: =B17-C17-D17-E17 -> 15 | G17: =IF(C17+D17=0,0,C17/(C17+D17)) -> 0
A18: Auth - Passwords | B18: =COUNTIF('Test Cases'!$B$2:$B$500,$A18) -> 9 | C18: =COUNTIFS('Test Cases'!$B$2:$B$500,$A18,'Test Cases'!$L$2:$L$500,"Pass") -> 0 | D18: =COUNTIFS('Test Cases'!$B$2:$B$500,$A18,'Test Cases'!$L$2:$L$500,"Fail") -> 0 | E18: =COUNTIFS('Test Cases'!$B$2:$B$500,$A18,'Test Cases'!$L$2:$L$500,"Blocked") -> 0 | F18: =B18-C18-D18-E18 -> 9 | G18: =IF(C18+D18=0,0,C18/(C18+D18)) -> 0
A19: Customer (B2C) | B19: =COUNTIF('Test Cases'!$B$2:$B$500,$A19) -> 7 | C19: =COUNTIFS('Test Cases'!$B$2:$B$500,$A19,'Test Cases'!$L$2:$L$500,"Pass") -> 0 | D19: =COUNTIFS('Test Cases'!$B$2:$B$500,$A19,'Test Cases'!$L$2:$L$500,"Fail") -> 0 | E19: =COUNTIFS('Test Cases'!$B$2:$B$500,$A19,'Test Cases'!$L$2:$L$500,"Blocked") -> 0 | F19: =B19-C19-D19-E19 -> 7 | G19: =IF(C19+D19=0,0,C19/(C19+D19)) -> 0
A20: Agency (B2B) | B20: =COUNTIF('Test Cases'!$B$2:$B$500,$A20) -> 17 | C20: =COUNTIFS('Test Cases'!$B$2:$B$500,$A20,'Test Cases'!$L$2:$L$500,"Pass") -> 0 | D20: =COUNTIFS('Test Cases'!$B$2:$B$500,$A20,'Test Cases'!$L$2:$L$500,"Fail") -> 0 | E20: =COUNTIFS('Test Cases'!$B$2:$B$500,$A20,'Test Cases'!$L$2:$L$500,"Blocked") -> 0 | F20: =B20-C20-D20-E20 -> 17 | G20: =IF(C20+D20=0,0,C20/(C20+D20)) -> 0
A21: Admin - Users | B21: =COUNTIF('Test Cases'!$B$2:$B$500,$A21) -> 28 | C21: =COUNTIFS('Test Cases'!$B$2:$B$500,$A21,'Test Cases'!$L$2:$L$500,"Pass") -> 0 | D21: =COUNTIFS('Test Cases'!$B$2:$B$500,$A21,'Test Cases'!$L$2:$L$500,"Fail") -> 0 | E21: =COUNTIFS('Test Cases'!$B$2:$B$500,$A21,'Test Cases'!$L$2:$L$500,"Blocked") -> 0 | F21: =B21-C21-D21-E21 -> 28 | G21: =IF(C21+D21=0,0,C21/(C21+D21)) -> 0
A22: Admin - Agencies | B22: =COUNTIF('Test Cases'!$B$2:$B$500,$A22) -> 8 | C22: =COUNTIFS('Test Cases'!$B$2:$B$500,$A22,'Test Cases'!$L$2:$L$500,"Pass") -> 0 | D22: =COUNTIFS('Test Cases'!$B$2:$B$500,$A22,'Test Cases'!$L$2:$L$500,"Fail") -> 0 | E22: =COUNTIFS('Test Cases'!$B$2:$B$500,$A22,'Test Cases'!$L$2:$L$500,"Blocked") -> 0 | F22: =B22-C22-D22-E22 -> 8 | G22: =IF(C22+D22=0,0,C22/(C22+D22)) -> 0
A23: Staff | B23: =COUNTIF('Test Cases'!$B$2:$B$500,$A23) -> 7 | C23: =COUNTIFS('Test Cases'!$B$2:$B$500,$A23,'Test Cases'!$L$2:$L$500,"Pass") -> 0 | D23: =COUNTIFS('Test Cases'!$B$2:$B$500,$A23,'Test Cases'!$L$2:$L$500,"Fail") -> 0 | E23: =COUNTIFS('Test Cases'!$B$2:$B$500,$A23,'Test Cases'!$L$2:$L$500,"Blocked") -> 0 | F23: =B23-C23-D23-E23 -> 7 | G23: =IF(C23+D23=0,0,C23/(C23+D23)) -> 0
A24: Documents | B24: =COUNTIF('Test Cases'!$B$2:$B$500,$A24) -> 5 | C24: =COUNTIFS('Test Cases'!$B$2:$B$500,$A24,'Test Cases'!$L$2:$L$500,"Pass") -> 0 | D24: =COUNTIFS('Test Cases'!$B$2:$B$500,$A24,'Test Cases'!$L$2:$L$500,"Fail") -> 0 | E24: =COUNTIFS('Test Cases'!$B$2:$B$500,$A24,'Test Cases'!$L$2:$L$500,"Blocked") -> 0 | F24: =B24-C24-D24-E24 -> 5 | G24: =IF(C24+D24=0,0,C24/(C24+D24)) -> 0
A25: Security | B25: =COUNTIF('Test Cases'!$B$2:$B$500,$A25) -> 5 | C25: =COUNTIFS('Test Cases'!$B$2:$B$500,$A25,'Test Cases'!$L$2:$L$500,"Pass") -> 0 | D25: =COUNTIFS('Test Cases'!$B$2:$B$500,$A25,'Test Cases'!$L$2:$L$500,"Fail") -> 0 | E25: =COUNTIFS('Test Cases'!$B$2:$B$500,$A25,'Test Cases'!$L$2:$L$500,"Blocked") -> 0 | F25: =B25-C25-D25-E25 -> 5 | G25: =IF(C25+D25=0,0,C25/(C25+D25)) -> 0
A26: Total | B26: =SUM(B15:B25) -> 111 | C26: =SUM(C15:C25) -> 0 | D26: =SUM(D15:D25) -> 0 | E26: =SUM(E15:E25) -> 0 | F26: =SUM(F15:F25) -> 111 | G26: =IF(C26+D26=0,0,C26/(C26+D26)) -> 0
A27: Check: module total equals total test cases | B27: =IF(B26=B4,"OK","Mismatch - a module name is misspelled") -> OK
A29: How to use this sheet
A30: 1. Run the test in Postman using the 'Postman request' column. Follow 'Steps / test data'.
A31: 2. Fill the yellow cells on 'Test Cases': Actual status (the HTTP code you got), Result (dropdown), Notes / bug ID, Tested on (date).
A32: 3. If Actual status differs from Expected status, the number turns red. Set Result to Fail and note what you saw.
A33: 4. Use Blocked when you cannot run a test (for example no OTP yet). This Summary updates by itself.
A34: 5. Suggested order: System > Admin login > Customer > Agency > Admin agencies > Staff > Documents > Security.
A35: 6. Expected status codes come from documentation/openapi.json. If your API behaves differently on purpose, update the expected value.
A36: 7. Add new cases in the empty formatted rows at the bottom of 'Test Cases'. Use an exact module name from the table above.
A38: Colour key: yellow cells are for you to fill; everything else is pre-filled.

Sheet Test Cases
A1: Test ID | B1: Module | C1: Test case | D1: Login as | E1: Method | F1: Endpoint | G1: Postman request (folder > name) | H1: Steps / test data | I1: Expected status | J1: Expected result | K1: Actual status | L1: Result | M1: Notes / bug ID | N1: Tested on
A2: SYS-01 | B2: System | C2: Health check | D2: None | E2: GET | F2: /health | G2: 00 - Quick start > Health check | H2: Server and Atlas connection running. | I2: 200 | J2: Body has success:true and db:"up". | L2: Not Run
A3: SYS-02 | B3: System | C3: API root / version | D3: None | E3: GET | F3: / | G3: 10 - System > API version | H3: Send with no token. | I3: 200 | J3: success:true, message "API is running.", version present. | L3: Not Run
A4: REG-01 | B4: Auth - Register & OTP | C4: Register customer with valid data | D4: None | E4: POST | F4: /api/auth/register | G4: 02 - Auth > Register a customer (B2C) | H4: Use {{customerEmail}} / {{customerPassword}}. Fresh email. | I4: 201 | J4: user.role = B2C, status PENDING, otpSent:true. New line appears in mail.jsonl. | L4: Not Run
A5: REG-02 | B5: Auth - Register & OTP | C5: Register with an email that already exists | D5: None | E5: POST | F5: /api/auth/register | G5: 02 - Auth > Register a customer (B2C) | H5: Send the same body a second time. | I5: 409 | J5: code EMAIL_TAKEN. | L5: Not Run
A6: REG-03 | B6: Auth - Register & OTP | C6: Register with a weak password | D6: None | E6: POST | F6: /api/auth/register | G6: 02 - Auth > Register a customer (B2C) | H6: Change password to abc12345 (no upper case / symbol). | I6: 422 | J6: code VALIDATION_ERROR, errors[] names the password field. | L6: Not Run
A7: REG-04 | B7: Auth - Register & OTP | C7: Register with an invalid email | D7: None | E7: POST | F7: /api/auth/register | G7: 02 - Auth > Register a customer (B2C) | H7: Change email to not-an-email. | I7: 422 | J7: code VALIDATION_ERROR, errors[] names the email field. | L7: Not Run
A8: REG-05 | B8: Auth - Register & OTP | C8: Login before email is verified | D8: None | E8: POST | F8: /api/auth/login | G8: 02 - Auth > Log in (email and password) | H8: Right after register, before verifying OTP. | I8: 403 | J8: code EMAIL_NOT_VERIFIED. | L8: Not Run
A9: REG-06 | B9: Auth - Register & OTP | C9: Verify email with a wrong code | D9: None | E9: POST | F9: /api/auth/verify-otp | G9: 02 - Auth > Verify email code | H9: Set otp = 000000. | I9: 400 | J9: code INVALID_CODE. | L9: Not Run
A10: REG-07 | B10: Auth - Register & OTP | C10: Verify email with the correct code | D10: None | E10: POST | F10: /api/auth/verify-otp | G10: 02 - Auth > Verify email code | H10: Copy newest otp for this email from mail.jsonl into {{otp}}. | I10: 200 | J10: Message "Email verified." User becomes ACTIVE. | L10: Not Run
A11: REG-08 | B11: Auth - Register & OTP | C11: Resend verification code | D11: None | E11: POST | F11: /api/auth/resend-otp | G11: 02 - Auth > Resend verification code | H11: Wait 60 s cooldown if needed. | I11: 200 | J11: Generic message; a new line appears in mail.jsonl. | L11: Not Run
A12: LOG-01 | B12: Auth - Login & Session | C12: Login as customer with valid credentials | D12: None | E12: POST | F12: /api/auth/login | G12: 00 - Quick start > Login as CUSTOMER (B2C) | H12: Verified customer account. | I12: 200 | J12: data.accessToken present, user.role = B2C. Tests "Role is B2C" green; bearerToken saved. | L12: Not Run
A13: LOG-02 | B13: Auth - Login & Session | C13: Login as admin with valid credentials | D13: None | E13: POST | F13: /api/auth/login | G13: 00 - Quick start > Login as ADMIN | H13: Admin seeded with npm run seed. | I13: 200 | J13: user.role = ADMIN. Test "Role is ADMIN" green. | L13: Not Run
... A35: PWD-09 | B35: Auth - Passwords | C35: Change password to a weak password | D35: Customer | E35: POST | F35: /api/auth/change-password | G35: 02 - Auth > Change password (signed in) | H35: newPassword = 12345678. | I35: 422 | J35: code VALIDATION_ERROR. | L35: Not Run
A36: B2C-01 | B36: Customer (B2C) | C36: Get my profile | D36: Customer | E36: GET | F36: /api/b2c/profile | G36: 03 - Customer (B2C) > My profile | I36: 200 | J36: Own profile returned. | L36: Not Run
A37: B2C-02 | B37: Customer (B2C) | C37: Update my profile | D37: Customer | E37: PATCH | F37: /api/b2c/profile | G37: 03 - Customer (B2C) > Update my profile | H37: Change name and phone. | I37: 200 | J37: Updated values returned; GET shows the same values. | L37: Not Run
A38: B2C-03 | B38: Customer (B2C) | C38: Update profile with an invalid phone | D38: Customer | E38: PATCH | F38: /api/b2c/profile | G38: 03 - Customer (B2C) > Update my profile | H38: phone = 123. | I38: 422 | J38: code VALIDATION_ERROR. | L38: Not Run
A39: B2C-04 | B39: Customer (B2C) | C39: Customer profile without a token | D39: None | E39: GET | F39: /api/b2c/profile | G39: 03 - Customer (B2C) > My profile | H39: No bearer token. | I39: 401 | J39: Unauthorized. | L39: Not Run
A40: B2C-05 | B40: Customer (B2C) | C40: RBAC: customer calls an admin route | D40: Customer | E40: GET | F40: /api/admin/users | G40: 06 - Admin: users > List users | H40: Logged in as customer. | I40: 403 | J40: Forbidden; no user list returned. | L40: Not Run
A41: B2C-06 | B41: Customer (B2C) | C41: RBAC: customer calls an agency route | D41: Customer | E41: GET | F41: /api/b2b/profile | G41: 04 - Agency (B2B) > My profile and partner record | H41: Logged in as customer. | I41: 403 | J41: Forbidden. | L41: Not Run
A42: B2C-07 | B42: Customer (B2C) | C42: RBAC: customer calls a staff route | D42: Customer | E42: GET | F42: /api/staff/partners | G42: 05 - Staff > List agencies (read only) | H42: Logged in as customer. | I42: 403 | J42: Forbidden. | L42: Not Run
A43: B2B-01 | B43: Agency (B2B) | C43: Register agency with valid data and trade license | D43: None | E43: POST | F43: /api/auth/b2b/register | G43: 02 - Auth > Register an agency (B2B) | H43: Attach a PDF/JPG/PNG (under 5 MB) to tradeLicense. | I43: 201 | J43: user.role = B2B, status PENDING; partner record created; partnerId saved; OTP in mail.jsonl. | L43: Not Run
A44: B2B-02 | B44: Agency (B2B) | C44: Register agency without a trade license file | D44: None | E44: POST | F44: /api/auth/b2b/register | G44: 02 - Auth > Register an agency (B2B) | H44: Remove the tradeLicense file. | I44: 422 | J44: code VALIDATION_ERROR, error on tradeLicense. | L44: Not Run
A45: B2B-03 | B45: Agency (B2B) | C45: Register agency with a disallowed file type | D45: None | E45: POST | F45: /api/auth/b2b/register | G45: 02 - Auth > Register an agency (B2B) | H45: Attach a .txt or .exe file. | I45: 400 | J45: code FILE_TYPE_NOT_ALLOWED. | L45: Not Run
A46: B2B-04 | B46: Agency (B2B) | C46: Register agency with a file over 5 MB | D46: None | E46: POST | F46: /api/auth/b2b/register | G46: 02 - Auth > Register an agency (B2B) | H46: Attach a file larger than 5 MB. | I46: 413 | J46: Payload too large; nothing is created. | L46: Not Run
A47: B2B-05 | B47: Agency (B2B) | C47: Register agency with an existing email | D47: None | E47: POST | F47: /api/auth/b2b/register | G47: 02 - Auth > Register an agency (B2B) | H47: Reuse {{agencyEmail}}. | I47: 409 | J47: code EMAIL_TAKEN. | L47: Not Run
A48: B2B-06 | B48: Agency (B2B) | C48: Agency login before email verification | D48: None | E48: POST | F48: /api/auth/login | G48: 00 - Quick start > Login as AGENCY (B2B) | H48: Before verifying OTP. | I48: 403 | J48: code EMAIL_NOT_VERIFIED. | L48: Not Run
A49: B2B-07 | B49: Agency (B2B) | C49: Verify agency email | D49: None | E49: POST | F49: /api/auth/verify-otp | G49: 02 - Auth > Verify email code | H49: Email = {{agencyEmail}}; newest otp from mail.jsonl. | I49: 200 | J49: Email verified. | L49: Not Run
A50: B2B-08 | B50: Agency (B2B) | C50: Agency login after verification | D50: None | E50: POST | F50: /api/auth/login | G50: 00 - Quick start > Login as AGENCY (B2B) | I50: 200 | J50: user.role = B2B. Test "Role is B2B" green. | L50: Not Run
A51: B2B-09 | B51: Agency (B2B) | C51: Get agency profile and partner record | D51: Agency | E51: GET | F51: /api/b2b/profile | G51: 04 - Agency (B2B) > My profile and partner record | I51: 200 | J51: User and partner (company, license, documents) returned. | L51: Not Run
A52: B2B-10 | B52: Agency (B2B) | C52: Update agency profile | D52: Agency | E52: PATCH | F52: /api/b2b/profile | G52: 04 - Agency (B2B) > Update my profile | H52: Change address and businessType. | I52: 200 | J52: Updated values returned. | L52: Not Run
A53: B2B-11 | B53: Agency (B2B) | C53: List my documents | D53: Agency | E53: GET | F53: /api/b2b/documents | G53: 04 - Agency (B2B) > My documents and their review status | I53: 200 | J53: TRADE_LICENSE listed with status PENDING. | L53: Not Run
A54: B2B-12 | B54: Agency (B2B) | C54: Upload an extra document | D54: Agency | E54: POST | F54: /api/b2b/documents | G54: 04 - Agency (B2B) > Upload more documents | H54: Attach a valid file to businessCard. | I54: 201 | J54: New document added with status PENDING. | L54: Not Run
A55: B2B-13 | B55: Agency (B2B) | C55: Upload an extra document with a bad file type | D55: Agency | E55: POST | F55: /api/b2b/documents | G55: 04 - Agency (B2B) > Upload more documents | H55: Attach a .txt file. | I55: 400 | J55: code FILE_TYPE_NOT_ALLOWED. | L55: Not Run
A56: B2B-14 | B56: Agency (B2B) | C56: Operational overview before approval | D56: Agency | E56: GET | F56: /api/b2b/overview | G56: 04 - Agency (B2B) > Operational overview (approved agencies only) | H56: Agency still PENDING. | I56: 403 | J56: code PARTNER_NOT_APPROVED. | L56: Not Run
A57: B2B-15 | B57: Agency (B2B) | C57: Operational overview after approval | D57: Agency | E57: GET | F57: /api/b2b/overview | G57: 04 - Agency (B2B) > Operational overview (approved agencies only) | H57: After admin approves the agency; login again. | I57: 200 | J57: Overview returned. | L57: Not Run
A58: B2B-16 | B58: Agency (B2B) | C58: RBAC: agency calls an admin route | D58: Agency | E58: GET | F58: /api/admin/b2b | G58: 07 - Admin: agencies > List agencies | H58: Logged in as agency. | I58: 403 | J58: Forbidden. | L58: Not Run
A59: B2B-17 | B59: Agency (B2B) | C59: RBAC: agency calls a staff route | D59: Agency | E59: GET | F59: /api/staff/partners | G59: 05 - Staff > List agencies (read only) | H59: Logged in as agency. | I59: 403 | J59: Forbidden. | L59: Not Run
A60: ADU-01 | B60: Admin - Users | C60: List users | D60: Admin | E60: GET | F60: /api/admin/users | G60: 06 - Admin: users > List users | I60: 200 | J60: data[] with meta (total, page, limit, totalPages); userId saved. | L60: Not Run
A61: ADU-02 | B61: Admin - Users | C61: List users filtered by role | D61: Admin | E61: GET | F61: /api/admin/users | G61: 06 - Admin: users > List users | H61: Enable the role=B2C query param. | I61: 200 | J61: Only B2C users returned. | L61: Not Run
...

Sheet Test Data
A1: Variable | B1: Where | C1: Example value | D1: Used for / note
A2: baseUrl | B2: Environment | C2: http://localhost:5000 | D2: API address.
A3: adminEmail | B3: Environment | C3: (your ADMIN_SEED_EMAIL) | D3: Must equal ADMIN_SEED_EMAIL in .env.
A4: adminPassword | B4: Environment | C4: (your ADMIN_SEED_PASSWORD) | D4: Must equal ADMIN_SEED_PASSWORD in .env. 8+ chars, upper, lower, number, symbol.
A5: customerEmail | B5: Environment | C5: customer1@example.com | D5: Customer account created by the Register test.
A6: customerPassword | B6: Environment | C6: Str0ng!Pass | D6: Update after the change-password / reset tests.
A7: agencyEmail | B7: Environment | C7: agency1@example.com | D7: Agency account created by the agency register test.
A8: agencyPassword | B8: Environment | C8: Str0ng!Pass | D8: Agency password.
A9: staffEmail | B9: Environment | C9: staff1@example.com | D9: Staff account created by the admin.
A10: staffPassword | B10: Environment | C10: Sara@Pass12 | D10: Password set through setup-account.
A11: newPassword | B11: Environment | C11: N3w!Passw0rd | D11: Used by reset / change password tests.
A12: otp | B12: Environment | C12: 123456 | D12: Newest code for the right email, copied from mail.jsonl. Valid 10 minutes, 5 wrong tries allowed.
... A14: clientType | B14: Environment | C14: (empty) or mobile | D14: Empty = refresh token in cookie. mobile = refresh token in body.
A15: bearerToken | B15: Collection (auto) | D15: Set by the Login requests. Expires after 15 minutes.
A16: userId / partnerId / docId | B16: Collection (auto) | D16: Set when you list users or agencies. Check them before DELETE or status tests.
A17: mail.jsonl | B17: Project root | D17: Every 'sent' email is one JSON line (needs EMAIL_PROVIDER=file and MAIL_OUTBOX_FILE=./mail.jsonl in .env, then restart the server).
A18: Test files | B18: Your computer | C18: license.pdf (<5 MB), notes.txt, big.pdf (>5 MB) | D18: Valid file, disallowed type, and too-large file for the upload tests.

Sheet Bug Log
A1: Bug ID | B1: Test ID | C1: Title | D1: Severity | E1: Steps to reproduce | F1: Expected | G1: Actual | H1: Status | I1: Found on
A2: EXAMPLE-01 | B2: LOG-03 | C2: Wrong password returns 500 (example row - delete me) | D2: Medium | E2: 1. POST /api/auth/login with a valid email and a wrong password | F2: 401 INVALID_CREDENTIALS | G2: 500 Internal Server Error | H2: Open
